Got the Test Exception
Inside finally block